<?xml version="1.0" ?>
<robot name="robot">
  <link name="link_base">
    <visual>
      <geometry>
        <box size="0.005 0.00001 0.0001"/>
      </geometry>
      <origin rpy="0 0 0" xyz="0 0 0"/>
      <material name="link_base_material">
        <color rgba="1.0 1.0 1.0 1.0"/>
      </material>
    </visual>
  </link>
  <link name="link_x1_B">
    <visual>
      <geometry>
        <box size="0.005 0.015 0.0001"/>
      </geometry>
      <origin rpy="0 0 0" xyz="0 -0.0075 0"/>
      <material name="link_x1_B_material">
        <color rgba="1.0 0.0 0.0 1.0"/>
      </material>
    </visual>
  </link>
  <joint name="joint_base_x1" type="fixed">
    <parent link="link_base"/>
    <child link="link_x1_B"/>
    <origin xyz="0 -0.00 0" rpy="0 0 0"/>
    <axis xyz="1 0 0"/>
    <limit effort="1" velocity="20"/>
  </joint>
  <link name="link_x1_A">
    <visual>
      <geometry>
        <box size="0.005 0.0185 0.0001"/>
      </geometry>
      <origin rpy="0 0 0" xyz="0 -0.00925 0"/>
      <material name="link_x1_A_material">
        <color rgba="0.0 1.0 0.0 1.0"/>
      </material>
    </visual>
  </link>
  <joint name="joint_x1_A" type="fixed">
    <parent link="link_x1_B"/>
    <child link="link_x1_A"/>
    <origin xyz="0 -0.015 0" rpy="2.0943951023931957 0 0"/>
    <axis xyz="1 0 0"/>
    <limit effort="1" velocity="20"/>
  </joint>
  <link name="link_A_C">
    <visual>
      <geometry>
        <box size="0.005 0.07999999999999999 0.0001"/>
      </geometry>
      <origin rpy="0 0 0" xyz="0 -0.039999999999999994 0"/>
      <material name="link_A_C_material">
        <color rgba="0.0 0.0 1.0 1.0"/>
      </material>
    </visual>
  </link>
  <joint name="joint_AC" type="revolute">
    <parent link="link_x1_A"/>
    <child link="link_A_C"/>
    <origin xyz="0 -0.0185 0" rpy="-1.9634954084936207 0 0"/>
    <axis xyz="1 0 0"/>
    <limit lower="0" upper="3.141592653589793" effort="1" velocity="20"/>
  </joint>
  <link name="link_X1_X2">
    <visual>
      <geometry>
        <box size="0.005 0.09999999999999999 0.0001"/>
      </geometry>
      <origin rpy="0 0 0" xyz="0 -0.049999999999999996 0"/>
      <material name="link_X1_X2_material">
        <color rgba="0.2 0.0 0.3 1.0"/>
      </material>
    </visual>
  </link>
  <joint name="joint_X1_X2" type="revolute">
    <parent link="link_x1_B"/>
    <child link="link_X1_X2"/>
    <origin xyz="0.005 -0.015 0" rpy="0.5235987755982991 0 0"/>
    <axis xyz="1 0 0"/>
    <limit lower="0" upper="3.141592653589793" effort="1" velocity="20"/>
  </joint>
  <link name="link_X2_C">
    <visual>
      <geometry>
        <box size="0.005 0.028 0.0001"/>
      </geometry>
      <origin rpy="0 0 0" xyz="0 -0.014 0"/>
      <material name="link_X2_C_material">
        <color rgba="0.2 0.3 0.0 1.0"/>
      </material>
    </visual>
  </link>
  <joint name="joint_X2_C" type="revolute">
    <parent link="link_X1_X2"/>
    <child link="link_X2_C"/>
    <origin xyz="0 -0.09999999999999999 0" rpy="-2.7068710845240815 0 0"/>
    <axis xyz="1 0 0"/>
    <limit lower="0" upper="3.141592653589793" effort="1" velocity="20"/>
  </joint>
  <link name="link_C_D">
    <visual>
      <geometry>
        <box size="0.005 0.044 0.0001"/>
      </geometry>
      <origin rpy="0 0 0" xyz="0 -0.022 0"/>
      <material name="link_C_D_material">
        <color rgba="0.0 0.2 0.3 1.0"/>
      </material>
    </visual>
  </link>
  <joint name="joint_CD_CX2" type="fixed">
    <parent link="link_X2_C"/>
    <child link="link_C_D"/>
    <origin xyz="-0.005  -0.028 0" rpy="1.9634954084936207  0 0"/>
    <axis xyz="1 0 0"/>
    <limit effort="1" velocity="20"/>
  </joint>
  <link name="closing_link_1">
    <visual>
      <geometry>
        <box size="0.002 0.002 0.002"/>
      </geometry>
      <origin rpy="0 0 0" xyz="0 0 0"/>
      <material name="closing_link_1_material">
        <color rgba="0.2 0.2 0.2 1.0"/>
      </material>
    </visual>
  </link>
  <joint name="new_closing_joint_1" type="fixed">
    <parent link="link_A_C"/>
    <child link="closing_link_1"/>
    <origin xyz="0 -0.07999999999999999 0" rpy="0 0 0"/>
    <axis xyz="1 0 0"/>
    <limit effort="1" velocity="20"/>
  </joint>
  <link name="closing_link_2">
    <visual>
      <geometry>
        <box size="0.002 0.002 0.002"/>
      </geometry>
      <origin rpy="0 0 0" xyz="0 0 0"/>
      <material name="closing_link_2_material">
        <color rgba="0.9 0.6 0.2 1.0"/>
      </material>
    </visual>
  </link>
  <joint name="new_closing_joint_2" type="fixed">
    <parent link="link_X2_C"/>
    <child link="closing_link_2"/>
    <origin xyz="0 -0.028 0" rpy="0 0 0"/>
    <axis xyz="1 0 0"/>
    <limit effort="1" velocity="20"/>
  </joint>
  <link name="new_fingertips_link">
    <visual>
      <geometry>
        <box size="0.01 0.01 0.01"/>
      </geometry>
      <origin rpy="0 0 0" xyz="0 0 0"/>
      <material name="new_fingertips_link_material">
        <color rgba="0.1 0.3 0.5 1.0"/>
      </material>
    </visual>
  </link>
  <joint name="joint_close_finger" type="fixed">
    <parent link="link_C_D"/>
    <child link="new_fingertips_link"/>
    <origin xyz="0 -0.033 0" rpy="3.141592653589793 1.5707963267948966 0"/>
    <axis xyz="1 0 0"/>
    <limit effort="1" velocity="20"/>
  </joint>
</robot>
